import React from "react";
import { useState, useEffect } from "react";
import Card from "../UI/Card";
import classes from "./AvailableMeals.module.css";
import MealItem from "./MealItem/MealItem";

const DUMMY_MEALS = [
  {
    id: "m1",
    name: "Sushi",
    description: "Finest fish and veggies",
    price: 22.99,
  },
  {
    id: "m2",
    name: "Schnitzel",
    description: "A german specialty!",
    price: 16.5,
  },
  {
    id: "m3",
    name: "Barbecue Burger",
    description: "American, raw, meaty",
    price: 12.99,
  },
  {
    id: "m4",
    name: "Green Bowl",
    description: "Healthy...and green...",
    price: 18.99,
  },
];

const AvailableMeals = () => {
  const [meals, setMeals] = useState([]);
  const [isLoading, setIsLoading] = useState(true);
  const [httpError, setHttpError] = useState();

  useEffect(() => {
    // NOTE: since, useEffect callback can't return a promise,i.e. useEffect(async()=>{await...})
    // NOTE: so creating a new fn with async await
    const fetchMeals = async () => {
      const response = await fetch(
        "https://custom-http-hook-163f2-default-rtdb.firebaseio.com/meals.json"
      );
      if (!response.ok) {
        // NOTE: this string will be stored in the message property of error object
        throw new Error("Something went wrong");
        //DEBUG: Here we are throwing error inside a promise which makes the promise to reject
      }
      const responseData = await response.json();
      const loadedMeals = [];
      for (const key in responseData) {
        loadedMeals.push({
          id: key,
          name: responseData[key].name,
          description: responseData[key].description,
          price: responseData[key].price,
        });
      }
      setMeals(loadedMeals);
      setIsLoading(false);
    };
    // DEBUG: we can't use try catch to wrap it unless we also await fetchMeals() for which we'll have to turn
    // DEBUG: our useEffect function into an asnc function which is not allowed
    // DEBUG: other approach, put try catch block into a seperate function - for error handling and use async await there
    // try {
    //   fetchMeals();
    // } catch (error) {
    //   setIsLoading(false);
    //   setHttpError(error.message);
    // }
    // NOTE: Solution using .then() .catch()
    fetchMeals().catch((error) => {
      setIsLoading(false);
      setHttpError(error.message);
    });
  }, []);

  if (isLoading) {
    return (
      <section className={classes.MealsLoading}>
        <p>Loading ...</p>
      </section>
    );
  }

  if (httpError) {
    return (
      <section className={classes.MealsError}>
        <p>{httpError}</p>
      </section>
    );
  }

  const mealsList = meals.map((meal) => {
    return (
      <MealItem
        id={meal.id}
        key={meal.id}
        name={meal.name}
        description={meal.description}
        price={meal.price}
      />
    );
  });
  return (
    <section className={classes.meals}>
      <Card>
        <ul>{mealsList}</ul>
      </Card>
    </section>
  );
};

export default AvailableMeals;
